import React from 'react';
import { render, screen } from '@testing-library/react';
import { ErrorBoundary } from '../ErrorBoundary';

// Componente que lanza error para testing
const ThrowError = ({ shouldThrow }: { shouldThrow: boolean }) => {
  if (shouldThrow) {
    throw new Error('Test error');
  }
  return <div>No error</div>;
};

describe('ErrorBoundary', () => {
  beforeEach(() => {
    // Suprimir console.error para tests
    jest.spyOn(console, 'error').mockImplementation(() => {});
  });

  afterEach(() => {
    jest.restoreAllMocks();
  });

  it('renders children when there is no error', () => {
    render(
      <ErrorBoundary>
        <ThrowError shouldThrow={false} />
      </ErrorBoundary>
    );

    expect(screen.getByText('No error')).toBeInTheDocument();
  });

  it('renders error UI when there is an error', () => {
    render(
      <ErrorBoundary>
        <ThrowError shouldThrow={true} />
      </ErrorBoundary>
    );

    expect(screen.getByText('Algo salió mal')).toBeInTheDocument();
    expect(screen.getByText('Ha ocurrido un error inesperado. Por favor, recarga la página.')).toBeInTheDocument();
    expect(screen.getByText('Recargar página')).toBeInTheDocument();
    expect(screen.getByText('Intentar de nuevo')).toBeInTheDocument();
  });

  it('renders custom fallback when provided', () => {
    const customFallback = <div>Custom error message</div>;

    render(
      <ErrorBoundary fallback={customFallback}>
        <ThrowError shouldThrow={true} />
      </ErrorBoundary>
    );

    expect(screen.getByText('Custom error message')).toBeInTheDocument();
  });

  it('calls onError callback when error occurs', () => {
    const onError = jest.fn();

    render(
      <ErrorBoundary onError={onError}>
        <ThrowError shouldThrow={true} />
      </ErrorBoundary>
    );

    expect(onError).toHaveBeenCalledWith(
      expect.any(Error),
      expect.objectContaining({
        componentStack: expect.any(String),
      })
    );
  });
});
